Workbook

Sheet AJ-L
A1: wh_id | B1: UN | C1: Cliente | D1: Sec Dir | E1: Nombre | F1: Dir 1 | G1: Dir 2 | H1: Dir 3 | I1: Num | J1: Ciudad | K1: Estado | L1: Factura | M1: Pedido | N1: Linea | O1: Item | P1: Descr | Q1: Cant Env | R1: Peso | S1: Volumen | T1: Comentarios | U1: Sabados | V1: Cita | W1: Placa | X1: Carga | Y1: Latitud | Z1: Longitud | AA1: Empresa | AB1: Conductor
A2: 1 | B2: AJI01 | C2: CDT1016687 | D2: 4 | E2: Reposteria Mars de Santa Gema S.A.S. | F2: Cl 76 56 47 | G2: Brr San Pablo | H2: Amars Reporteria | I2: 0 | J2: Itagui | K2: ANTIOQ | L2: AFE7180387 | M2: AJV9568212 | N2: 13 | O2: D751600 | P2: &16Oz Clear Sello Plus Cont w/Shallow lid 200Cs | Q2: 1 | R2: 4.5609 | S2: 0.0414 | T2: Recibe mercancía de Lunes a Sábado de 7:30am a 1:00pm y 2:00pm a 3:30pm. | U2: Y | V2: N | W2: USC439 | X2: L010894328 | Y2: 6.1891475 | Z2: -75.600571 | AA2: TDM TRANSPORTES S.A.S | AB2: 14324467
A3: 1 | B3: AJI01 | C3: CPR1028694 | D3: 4 | E3: Antonio`s Gelatos S.A.S. | F3: Kr 51 12 B Sur 55 Ps 1 | G3: Brr Guayabal | I3: 0 | J3: Medellín | K3: ANTIOQ | L3: AFE7180388 | M3: AJV9573508 | N3: 1 | O3: D102101 | P3: &8 1/3in White Round Foam Cake Liner 200Bg | Q3: 10 | R3: 12.451 | S3: 0.388 | T3: Recibe mercancía de Lunes a Sábado de 10:00am a 4:00pm. | U3: N | V3: N | W3: USC439 | X3: L010894328 | Y3: 0 | Z3: 0 | AA3: TDM TRANSPORTES S.A.S | AB3: 14324467
A4: 1 | B4: AJI01 | C4: CPR1028694 | D4: 4 | E4: Antonio`s Gelatos S.A.S. | F4: Kr 51 12 B Sur 55 Ps 1 | G4: Brr Guayabal | I4: 0 | J4: Medellín | K4: ANTIOQ | L4: AFE7180388 | M4: AJV9573508 | N4: 6 | O4: D750800G | P4: &8Oz Clear Sello Plus Cont w/Deep lid 200Cs | Q4: 2 | R4: 7.6698 | S4: 0.0778 | T4: Recibe mercancía de Lunes a Sábado de 10:00am a 4:00pm. | U4: N | V4: N | W4: USC439 | X4: L010894328 | Y4: 0 | Z4: 0 | AA4: TDM TRANSPORTES S.A.S | AB4: 14324467
A5: 1 | B5: AJI01 | C5: CPR1028694 | D5: 4 | E5: Antonio`s Gelatos S.A.S. | F5: Kr 51 12 B Sur 55 Ps 1 | G5: Brr Guayabal | I5: 0 | J5: Medellín | K5: ANTIOQ | L5: AFE7180388 | M5: AJV9573508 | N5: 8 | O5: D951150 | P5: N.1 Blue Dessert Spoon 100pk 1000Cs | Q5: 6 | R5: 15.9954 | S5: 0.0786 | T5: Recibe mercancía de Lunes a Sábado de 10:00am a 4:00pm. | U5: N | V5: N | W5: USC439 | X5: L010894328 | Y5: 0 | Z5: 0 | AA5: TDM TRANSPORTES S.A.S | AB5: 14324467
A6: 1 | B6: AJI01 | C6: IND1004255 | D6: 2 | E6: Cía.de Alimentos Colombianos Calco S.A. | F6: Carrera 43 A # 25 A-85 | I6: 0 | J6: Medellín | K6: ANTIOQ | L6: AFE7180389 | M6: AJV9574313 | N6: 1 | O6: D001200T | P6: Clear Lid for Foil Cont 4 13/16x3 7/8in 500Cs | Q6: 10 | R6: 22.514 | S6: 0.091 | T6: Entregar Pedido con Factura Original y Una Copia | U6: N | V6: N | W6: USC439 | X6: L010894328 | Y6: 6.2256559 | Z6: -75.569207 | AA6: TDM TRANSPORTES S.A.S | AB6: 14324467
A7: 1 | B7: AJI01 | C7: IND1013379 | D7: 3 | E7: Nuestra Cocina Artesanal S.A.S. | F7: Kr 43 C 61 Sur 10 | I7: 0 | J7: Sabaneta | K7: ANTIOQ | L7: AFE7180390 | M7: AJV9575348 | N7: 1 | O7: D001600T | P7: &Clear Lid for Foil Container 5 3/5x4 3/5in 500Cs | Q7: 12 | R7: 43.9512 | S7: 0.2112 | T7: Horario entrega mercancia: Lunes a Sabado de 6:00 am hasta la 1:00 pm. | U7: Y | V7: N | W7: USC439 | X7: L010894328 | Y7: 6.1545659 | Z7: -75.610311 | AA7: TDM TRANSPORTES S.A.S | AB7: 14324467
A8: 1 | B8: AJI01 | C8: IND1013379 | D8: 3 | E8: Nuestra Cocina Artesanal S.A.S. | F8: Kr 43 C 61 Sur 10 | I8: 0 | J8: Sabaneta | K8: ANTIOQ | L8: AFE7180390 | M8: AJV9575348 | N8: 2 | O8: D002300T | P8: &Clear Lid for Foil Cont 7 1/5x5in 500Cs | Q8: 5 | R8: 31.974 | S8: 0.123 | T8: Horario entrega mercancia: Lunes a Sabado de 6:00 am hasta la 1:00 pm. | U8: Y | V8: N | W8: USC439 | X8: L010894328 | Y8: 6.1545659 | Z8: -75.610311 | AA8: TDM TRANSPORTES S.A.S | AB8: 14324467
A9: 1 | B9: AJI01 | C9: IND1004174 | D9: 1 | E9: Pastelpan las Envinadas | F9: Carrera 50 GG # 10 B sur-81 | I9: 0 | J9: Medellín | K9: ANTIOQ | L9: AFE7180391 | M9: AJV9575358 | N9: 1 | O9: D004001 | P9: &8x8in White Foam Cake Liner 200Bg | Q9: 2 | R9: 3.12 | S9: 0.074 | T9: Se recibe mercancía de Lunes a Viernes de 7:00am a 2:00pm | U9: N | V9: N | W9: USC439 | X9: L010894328 | Y9: 6.1973047 | Z9: -75.586915 | AA9: TDM TRANSPORTES S.A.S | AB9: 14324467
A10: 1 | B10: AJI01 | C10: IND1004174 | D10: 1 | E10: Pastelpan las Envinadas | F10: Carrera 50 GG # 10 B sur-81 | I10: 0 | J10: Medellín | K10: ANTIOQ | L10: AFE7180391 | M10: AJV9575358 | N10: 2 | O10: D006801 | P10: &10 1/5x10 1/5in White Foam Cake Liner 200Bg | Q10: 1 | R10: 2.4105 | S10: 0.0612 | T10: Se recibe mercancía de Lunes a Viernes de 7:00am a 2:00pm | U10: N | V10: N | W10: USC439 | X10: L010894328 | Y10: 6.1973047 | Z10: -75.586915 | AA10: TDM TRANSPORTES S.A.S | AB10: 14324467
A11: 1 | B11: AJI01 | C11: IND1004174 | D11: 1 | E11: Pastelpan las Envinadas | F11: Carrera 50 GG # 10 B sur-81 | I11: 0 | J11: Medellín | K11: ANTIOQ | L11: AFE7180391 | M11: AJV9575358 | N11: 3 | O11: D100701 | P11: &3in White Round Foam Cake Liner 200Bg | Q11: 7 | R11: 1.1928 | S11: 0.0399 | T11: Se recibe mercancía de Lunes a Viernes de 7:00am a 2:00pm | U11: N | V11: N | W11: USC439 | X11: L010894328 | Y11: 6.1973047 | Z11: -75.586915 | AA11: TDM TRANSPORTES S.A.S | AB11: 14324467
A12: 1 | B12: AJI01 | C12: CPR1020631 | D12: 3 | E12: Chef Burger Company S.A.S. | F12: Kr 43 25a 127 | I12: 0 | J12: Medellín | K12: ANTIOQ | L12: AFE7180392 | M12: AJV9575536 | N12: 1 | O12: D631500TN | P12: &Clear Lid for 1 ½ -2-2 ½ Oz Souffle Cup 100pk 2500CS | Q12: 6 | R12: 25.0434 | S12: 0.24 | T12: Recibe mercancía de 7:00am a 2:00pm. | U12: N | V12: N | W12: USC439 | X12: L010894328 | Y12: 6.2254406 | Z12: -75.568378 | AA12: TDM TRANSPORTES S.A.S | AB12: 14324467
A13: 1 | B13: AJI01 | C13: CPR1020631 | D13: 3 | E13: Chef Burger Company S.A.S. | F13: Kr 43 25a 127 | I13: 0 | J13: Medellín | K13: ANTIOQ | L13: AFE7180392 | M13: AJV9575536 | N13: 2 | O13: D631599PN | P13: &1 ½Oz Black Shallow Souffle Cup 100 pk 2500Cs | Q13: 2 | R13: 9.393 | S13: 0.0944 | T13: Recibe mercancía de 7:00am a 2:00pm. | U13: N | V13: N | W13: USC439 | X13: L010894328 | Y13: 6.2254406 | Z13: -75.568378 | AA13: TDM TRANSPORTES S.A.S | AB13: 14324467
A14: 1 | B14: AJI01 | C14: IND1015580 | D14: 1 | E14: Activos Y Gastronomia Dos S.A.S. | F14: Cl 72 64 C 96 Bg Centro Norte Caribe 109 | G14: Brr Caribe | H14: Al Carbon Asados | I14: 0 | J14: Medellín | K14: ANTIOQ | L14: AFE7180393 | M14: AJV9575586 | N14: 1 | O14: D200101 | P14: &N.1 White Foam Tray 500Bg | Q14: 20 | R14: 27.6 | S14: 1.196 | T14: Enviar certificado de calidad de los productos No entregar mercancia entre las 11:30am y 2:00pm | U14: N | V14: N | W14: USC439 | X14: L010894328 | Y14: 6.2710203 | Z14: -75.575244 | AA14: TDM TRANSPORTES S.A.S | AB14: 14324467
A15: 1 | B15: AJI01 | C15: CPR1035667 | D15: 1 | E15: Cocorollo El Limonar S.A.S. | F15: Vda Portachuelo Auto Norte Km 20 | G15: Estadero Cocorollo | I15: 0 | J15: Girardota | K15: ANTIOQ | L15: AFE7180394 | M15: AJV9576242 | N15: 1 | O15: D771699YPS | P15: Black Tokyo Cont L PS 200Cs | Q15: 1 | R15: 5.7851 | S15: 0.0386 | T15: Recibe mercancía de Lunes a sábado de 6:00am a 3:00pm | U15: Y | V15: N | W15: USC439 | X15: L010894328 | Y15: 6.3802972 | Z15: -75.48032 | AA15: TDM TRANSPORTES S.A.S | AB15: 14324467
A16: 1 | B16: AJI01 | C16: CPR1035667 | D16: 1 | E16: Cocorollo El Limonar S.A.S. | F16: Vda Portachuelo Auto Norte Km 20 | G16: Estadero Cocorollo | I16: 0 | J16: Girardota | K16: ANTIOQ | L16: AFE7180394 | M16: AJV9576242 | N16: 2 | O16: DP73S00102 | P16: Translucent 1 oz ProToGo® Deli Container with Lid - S - Pk x | Q16: 15 | R16: 27.6 | S16: 0.315 | T16: Recibe mercancía de Lunes a sábado de 6:00am a 3:00pm | U16: Y | V16: N | W16: USC439 | X16: L010894328 | Y16: 6.3802972 | Z16: -75.48032 | AA16: TDM TRANSPORTES S.A.S | AB16: 14324467
A17: 1 | B17: AJI01 | C17: CMY1001954 | D17: 3 | E17: Arary S.A.S. | F17: Km 5+100 Auto Medellin Bogota Bodega 1A | G17: Parque Industrial Copacabana | I17: 0 | J17: Copacabana | K17: ANTIOQ | L17: AFE7180395 | M17: AJV9561811 | N17: 36 | O17: DP7301202 | P17: Translucent 12 oz ProToGo® Deli Container with Lid - L - Pk | Q17: 4 | R17: 14.8956 | S17: 0.1604 | T17: El transportador debe presentar carnet de afiliación a EPS y ARP para poder ingresar pedido a la bodega | U17: N | V17: N | W17: USC439 | X17: L010894328 | Y17: 6.3337526 | Z17: -75.533793 | AA17: TDM TRANSPORTES S.A.S | AB17: 14324467
A18: 1 | B18: AJI01 | C18: CMY1001954 | D18: 3 | E18: Arary S.A.S. | F18: Km 5+100 Auto Medellin Bogota Bodega 1A | G18: Parque Industrial Copacabana | I18: 0 | J18: Copacabana | K18: ANTIOQ | L18: AFE7180395 | M18: AJV9575191 | N18: 1 | O18: D001601T | P18: &Foam Lid for Foil Cont 5 3/5x4 3/5in 200Bg | Q18: 5 | R18: 2.926 | S18: 0.0815 | T18: El transportador debe presentar carnet de afiliación a EPS y ARP para poder ingresar pedido a la bodega | U18: N | V18: N | W18: USC439 | X18: L010894328 | Y18: 6.3337526 | Z18: -75.533793 | AA18: TDM TRANSPORTES S.A.S | AB18: 14324467
A19: 1 | B19: AJI01 | C19: CMY1001954 | D19: 3 | E19: Arary S.A.S. | F19: Km 5+100 Auto Medellin Bogota Bodega 1A | G19: Parque Industrial Copacabana | I19: 0 | J19: Copacabana | K19: ANTIOQ | L19: AFE7180395 | M19: AJV9575191 | N19: 2 | O19: D200101 | P19: &N.1 White Foam Tray 500Bg | Q19: 30 | R19: 41.4 | S19: 1.794 | T19: El transportador debe presentar carnet de afiliación a EPS y ARP para poder ingresar pedido a la bodega | U19: N | V19: N | W19: USC439 | X19: L010894328 | Y19: 6.3337526 | Z19: -75.533793 | AA19: TDM TRANSPORTES S.A.S | AB19: 14324467
A20: 1 | B20: AJI01 | C20: CMY1001954 | D20: 3 | E20: Arary S.A.S. | F20: Km 5+100 Auto Medellin Bogota Bodega 1A | G20: Parque Industrial Copacabana | I20: 0 | J20: Copacabana | K20: ANTIOQ | L20: AFE7180395 | M20: AJV9575191 | N20: 3 | O20: D200399 | P20: &N.3 Black Foam Tray 500Bg | Q20: 2 | R20: 4.948 | S20: 0.1854 | T20: El transportador debe presentar carnet de afiliación a EPS y ARP para poder ingresar pedido a la bodega | U20: N | V20: N | W20: USC439 | X20: L010894328 | Y20: 6.3337526 | Z20: -75.533793 | AA20: TDM TRANSPORTES S.A.S | AB20: 14324467
A21: 1 | B21: AJI01 | C21: CMY1001954 | D21: 3 | E21: Arary S.A.S. | F21: Km 5+100 Auto Medellin Bogota Bodega 1A | G21: Parque Industrial Copacabana | I21: 0 | J21: Copacabana | K21: ANTIOQ | L21: AFE7180395 | M21: AJV9575191 | N21: 4 | O21: D200401 | P21: &N.4 White Foam Tray 500Bg | Q21: 1 | R21: 3.7846 | S21: 0.1407 | T21: El transportador debe presentar carnet de afiliación a EPS y ARP para poder ingresar pedido a la bodega | U21: N | V21: N | W21: USC439 | X21: L010894328 | Y21: 6.3337526 | Z21: -75.533793 | AA21: TDM TRANSPORTES S.A.S | AB21: 14324467
A22: 1 | B22: AJI01 | C22: CMY1001954 | D22: 3 | E22: Arary S.A.S. | F22: Km 5+100 Auto Medellin Bogota Bodega 1A | G22: Parque Industrial Copacabana | I22: 0 | J22: Copacabana | K22: ANTIOQ | L22: AFE7180395 | M22: AJV9575191 | N22: 6 | O22: D200899 | P22: &N.8 Black Foam Tray 500Bg | Q22: 2 | R22: 9.6074 | S22: 0.3696 | T22: El transportador debe presentar carnet de afiliación a EPS y ARP para poder ingresar pedido a la bodega | U22: N | V22: N | W22: USC439 | X22: L010894328 | Y22: 6.3337526 | Z22: -75.533793 | AA22: TDM TRANSPORTES S.A.S | AB22: 14324467
A23: 1 | B23: AJI01 | C23: CMY1001954 | D23: 3 | E23: Arary S.A.S. | F23: Km 5+100 Auto Medellin Bogota Bodega 1A | G23: Parque Industrial Copacabana | I23: 0 | J23: Copacabana | K23: ANTIOQ | L23: AFE7180395 | M23: AJV9575191 | N23: 7 | O23: D201001 | P23: &N.10 White Foam Tray 500Bg | Q23: 1 | R23: 3.5803 | S23: 0.1267 | T23: El transportador debe presentar carnet de afiliación a EPS y ARP para poder ingresar pedido a la bodega | U23: N | V23: N | W23: USC439 | X23: L010894328 | Y23: 6.3337526 | Z23: -75.533793 | AA23: TDM TRANSPORTES S.A.S | AB23: 14324467
A24: 1 | B24: AJI01 | C24: CMY1001954 | D24: 3 | E24: Arary S.A.S. | F24: Km 5+100 Auto Medellin Bogota Bodega 1A | G24: Parque Industrial Copacabana | I24: 0 | J24: Copacabana | K24: ANTIOQ | L24: AFE7180395 | M24: AJV9575191 | N24: 9 | O24: D210101 | P24: &N.1-1 White Foam Tray 500Bg | Q24: 1 | R24: 1.3809 | S24: 0.0632 | T24: El transportador debe presentar carnet de afiliación a EPS y ARP para poder ingresar pedido a la bodega | U24: N | V24: N | W24: USC439 | X24: L010894328 | Y24: 6.3337526 | Z24: -75.533793 | AA24: TDM TRANSPORTES S.A.S | AB24: 14324467
A25: 1 | B25: AJI01 | C25: CMY1001954 | D25: 3 | E25: Arary S.A.S. | F25: Km 5+100 Auto Medellin Bogota Bodega 1A | G25: Parque Industrial Copacabana | I25: 0 | J25: Copacabana | K25: ANTIOQ | L25: AFE7180395 | M25: AJV9575191 | N25: 11 | O25: D402099 | P25: C-1 Black Hinged Lid Foam Cont 500Bg | Q25: 1 | R25: 2.7183 | S25: 0.144 | T25: El transportador debe presentar carnet de afiliación a EPS y ARP para poder ingresar pedido a la bodega | U25: N | V25: N | W25: USC439 | X25: L010894328 | Y25: 6.3337526 | Z25: -75.533793 | AA25: TDM TRANSPORTES S.A.S | AB25: 14324467
A26: 1 | B26: AJI01 | C26: CMY1001954 | D26: 3 | E26: Arary S.A.S. | F26: Km 5+100 Auto Medellin Bogota Bodega 1A | G26: Parque Industrial Copacabana | I26: 0 | J26: Copacabana | K26: ANTIOQ | L26: AFE7180395 | M26: AJV9575191 | N26: 14 | O26: D403199 | P26: &J-1 Black Hinged Lid Foam Cont 200Bg | Q26: 5 | R26: 11.913 | S26: 0.5335 | T26: El transportador debe presentar carnet de afiliación a EPS y ARP para poder ingresar pedido a la bodega | U26: N | V26: N | W26: USC439 | X26: L010894328 | Y26: 6.3337526 | Z26: -75.533793 | AA26: TDM TRANSPORTES S.A.S | AB26: 14324467
... A35: 1 | B35: AJI01 | C35: CMY1001954 | D35: 3 | E35: Arary S.A.S. | F35: Km 5+100 Auto Medellin Bogota Bodega 1A | G35: Parque Industrial Copacabana | I35: 0 | J35: Copacabana | K35: ANTIOQ | L35: AFE7180395 | M35: AJV9575195 | N35: 1 | O35: D200101 | P35: &N.1 White Foam Tray 500Bg | Q35: 36 | R35: 49.68 | S35: 2.1528 | T35: El transportador debe presentar carnet de afiliación a EPS y ARP para poder ingresar pedido a la bodega | U35: N | V35: N | W35: USC439 | X35: L010894328 | Y35: 6.3337526 | Z35: -75.533793 | AA35: TDM TRANSPORTES S.A.S | AB35: 14324467
A36: 1 | B36: AJI01 | C36: CDT1040851 | D36: 1 | E36: Durley Astrid Ramirez Ramirez | F36: Tv 56 A 57 19 Ps 2 | G36: Brr El Carretero | I36: 0 | J36: Bello | K36: ANTIOQ | L36: AFE7180396 | M36: AJV9519757 | N36: 1 | O36: D690801NL-I007067 | P36: !Vaso Espumado 8 oz Blanco - Pq x 20 un / CJ x 2000 un Imp. | Q36: 1 | R36: 2.7576 | S36: 0.2138 | U36: N | V36: N | W36: USC439 | X36: L010894328 | Y36: 6.3435003 | Z36: -75.56296 | AA36: TDM TRANSPORTES S.A.S | AB36: 14324467
A37: 1 | B37: AJI01 | C37: CDT1010327 | D37: 1 | E37: Jesus Horacio Arango Roldan | F37: Cl 45 79 A 100 | G37: Plaza Las Americas Lc 077 | H37: Distripana | I37: 0 | J37: Medellín | K37: ANTIOQ | L37: AFE7180397 | M37: AJV9531356 | N37: 21 | O37: PACK16-62 | P37: !Green HIPS Pack 9'' Plate, 6'' Plate, 7oz Cup, Fork, Knife, | Q37: 1 | R37: 2.4212 | S37: 0.0368 | T37: Recibe mercancia de Lunes a Viernes de 6:00am a 1:00pm. Presentar factura antes de entregar en Distripana Lc 077 | U37: N | V37: N | W37: USC439 | X37: L010894328 | Y37: 6.2518895 | Z37: -75.598643 | AA37: TDM TRANSPORTES S.A.S | AB37: 14324467
A38: 1 | B38: AJI01 | C38: CDT1041352 | D38: 1 | E38: Edgar David Vasquez Monsalve | F38: Cl 50 29 234 Ca Primer Piso | I38: 0 | J38: Copacabana | K38: ANTIOQ | L38: AFE7180398 | M38: AJV9537370 | N38: 3 | O38: DP7302402C | P38: Contenedor Deli ProToGo® 24 oz Opal - L - Pq x 50 un / CJ x | Q38: 1 | R38: 9.0939 | S38: 0.0709 | U38: N | V38: N | W38: USC439 | X38: L010894328 | Y38: 6.3543603 | Z38: -75.498692 | AA38: TDM TRANSPORTES S.A.S | AB38: 14324467
A39: 1 | B39: AJI01 | C39: CDT1041327 | D39: 1 | E39: Jorge Nelson Forigua Malagon | F39: Kr 15 4 16 | G39: Brr Aurelio Mejia | I39: 0 | J39: Girardota | K39: ANTIOQ | L39: AFE7180399 | M39: AJV9557879 | N39: 5 | O39: DP7301202 | P39: Translucent 12 oz ProToGo® Deli Container with Lid - L - Pk | Q39: 1 | R39: 3.7239 | S39: 0.0401 | T39: Horario entrega mercancia: Lunes A Viernes de 10:00 am A 4:00 pm y Sábados de 10:00 am A 2:00 pm. | U39: Y | V39: N | W39: USC439 | X39: L010894328 | Y39: 6.37895 | Z39: -75.444072 | AA39: TDM TRANSPORTES S.A.S | AB39: 14324467
A40: 1 | B40: AJI01 | C40: CDT1041410 | D40: 1 | E40: Carmen Johana Avendaño Rodriguez | F40: Cl 33 53 17 | G40: Brr Gran Avenida | I40: 0 | J40: Bello | K40: ANTIOQ | L40: AFE7180400 | M40: AJV9564279 | N40: 12 | O40: D720300 | P40: &Clear Venetian Cup 3Oz w/lid 20pk 500Cs | Q40: 1 | R40: 6.64 | S40: 0.05 | T40: Horario entrega mercancia: Lunes a Sábado de 9:00 am A 4:00 pm, Llamar al 3012750802. | U40: Y | V40: N | W40: USC439 | X40: L010894328 | Y40: 6.321114 | Z40: -75.559741 | AA40: TDM TRANSPORTES S.A.S | AB40: 14324467
A41: 1 | B41: AJI01 | C41: CDT1041410 | D41: 1 | E41: Carmen Johana Avendaño Rodriguez | F41: Cl 33 53 17 | G41: Brr Gran Avenida | I41: 0 | J41: Bello | K41: ANTIOQ | L41: AFE7180400 | M41: AJV9564279 | N41: 13 | O41: D720800 | P41: &Clear Venetian Cup 8Oz w/lid 20pk 500Cs | Q41: 1 | R41: 12.9136 | S41: 0.1016 | T41: Horario entrega mercancia: Lunes a Sábado de 9:00 am A 4:00 pm, Llamar al 3012750802. | U41: Y | V41: N | W41: USC439 | X41: L010894328 | Y41: 6.321114 | Z41: -75.559741 | AA41: TDM TRANSPORTES S.A.S | AB41: 14324467
A42: 1 | B42: AJI01 | C42: CDT1041410 | D42: 1 | E42: Carmen Johana Avendaño Rodriguez | F42: Cl 33 53 17 | G42: Brr Gran Avenida | I42: 0 | J42: Bello | K42: ANTIOQ | L42: AFE7180400 | M42: AJV9564279 | N42: 14 | O42: D721200 | P42: &Clear Venetian Cup 12Oz w/lid 20pk 500Cs | Q42: 2 | R42: 32.152 | S42: 0.2262 | T42: Horario entrega mercancia: Lunes a Sábado de 9:00 am A 4:00 pm, Llamar al 3012750802. | U42: Y | V42: N | W42: USC439 | X42: L010894328 | Y42: 6.321114 | Z42: -75.559741 | AA42: TDM TRANSPORTES S.A.S | AB42: 14324467
A43: 1 | B43: AJI01 | C43: CDT1041410 | D43: 1 | E43: Carmen Johana Avendaño Rodriguez | F43: Cl 33 53 17 | G43: Brr Gran Avenida | I43: 0 | J43: Bello | K43: ANTIOQ | L43: AFE7180400 | M43: AJV9564279 | N43: 15 | O43: D950100 | P43: &N.1 Clear Dessert Spoon 20pk 1000Cs | Q43: 1 | R43: 2.7052 | S43: 0.013 | T43: Horario entrega mercancia: Lunes a Sábado de 9:00 am A 4:00 pm, Llamar al 3012750802. | U43: Y | V43: N | W43: USC439 | X43: L010894328 | Y43: 6.321114 | Z43: -75.559741 | AA43: TDM TRANSPORTES S.A.S | AB43: 14324467
A44: 1 | B44: AJI01 | C44: CDT1041551 | D44: 1 | E44: Samuel Felipe Serna Patiño | F44: Kr 80 48 B 24 | G44: Brr La Floresta | H44: Distribuidora J1 | I44: 0 | J44: Medellín | K44: ANTIOQ | L44: AFE7180401 | M44: AJV9573002 | N44: 1 | O44: D200401 | P44: &N.4 White Foam Tray 500Bg | Q44: 1 | R44: 3.7846 | S44: 0.1407 | T44: Horario entrega mercancia: Lunes a Sábado de 9:00 am a 6:00 pm | U44: Y | V44: N | W44: USC439 | X44: L010894328 | Y44: 6.260324 | Z44: -75.597256 | AA44: TDM TRANSPORTES S.A.S | AB44: 14324467
A45: 1 | B45: AJI01 | C45: CDT1041551 | D45: 1 | E45: Samuel Felipe Serna Patiño | F45: Kr 80 48 B 24 | G45: Brr La Floresta | H45: Distribuidora J1 | I45: 0 | J45: Medellín | K45: ANTIOQ | L45: AFE7180401 | M45: AJV9573002 | N45: 6 | O45: DC07101200R | P45: &Round Cont Mini Pack S w/lid 300Cs | Q45: 1 | R45: 1.8794 | S45: 0.0238 | T45: Horario entrega mercancia: Lunes a Sábado de 9:00 am a 6:00 pm | U45: Y | V45: N | W45: USC439 | X45: L010894328 | Y45: 6.260324 | Z45: -75.597256 | AA45: TDM TRANSPORTES S.A.S | AB45: 14324467
A46: 1 | B46: AJI01 | C46: CDT1021331 | D46: 1 | E46: Lina Maria Taborda Restrepo | F46: Cl 63 129A 16 Brr San Cristobal | G46: Suministros Mi Corregimiento | I46: 0 | J46: Medellín | K46: ANTIOQ | L46: AFE7180402 | M46: AJV9573377 | N46: 1 | O46: D001601LT | P46: White Foam Lid for 16 oz Aluminum Container - Bg x 250 ea | Q46: 15 | R46: 9.393 | S46: 0.243 | T46: Recibe de Lunes a Viernes de 8 am a 4 pm | U46: N | V46: N | W46: USC439 | X46: L010894328 | Y46: 6.2791776 | Z46: -75.634524 | AA46: TDM TRANSPORTES S.A.S | AB46: 14324467
A47: 1 | B47: AJI01 | C47: CDT1039179 | D47: 1 | E47: Comercializadora GM & Asociados S.A.S | F47: Kr 83 21 02 | G47: Brr Belen Zafra | H47: Comercializadora GM & Asociados SAS | I47: 0 | J47: Medellín | K47: ANTIOQ | L47: AFE7180403 | M47: AJV9573474 | N47: 1 | O47: D201001 | P47: &N.10 White Foam Tray 500Bg | Q47: 1 | R47: 3.5803 | S47: 0.1267 | T47: Recibe mercancía de Lunes a Sábado de 9:00am a 5:00pm. No recibe mercancía los días Domingos ni Festivos. | U47: Y | V47: N | W47: USC439 | X47: L010894328 | Y47: 6.2265951 | Z47: -75.605828 | AA47: TDM TRANSPORTES S.A.S | AB47: 14324467
A48: 1 | B48: AJI01 | C48: CDT1039179 | D48: 1 | E48: Comercializadora GM & Asociados S.A.S | F48: Kr 83 21 02 | G48: Brr Belen Zafra | H48: Comercializadora GM & Asociados SAS | I48: 0 | J48: Medellín | K48: ANTIOQ | L48: AFE7180403 | M48: AJV9573474 | N48: 4 | O48: D950101 | P48: N.1 White Dessert Spoon 20pk 1000Cs | Q48: 1 | R48: 2.7052 | S48: 0.013 | T48: Recibe mercancía de Lunes a Sábado de 9:00am a 5:00pm. No recibe mercancía los días Domingos ni Festivos. | U48: Y | V48: N | W48: USC439 | X48: L010894328 | Y48: 6.2265951 | Z48: -75.605828 | AA48: TDM TRANSPORTES S.A.S | AB48: 14324467
...

Sheet FACTURAS
B1: =COUNTA(B3:B999) -> 212 | C1: =IF(B1>0,B1/23,0) -> 9.2173913 | E1: FECHA DESPACHO | F1: 45941 | I1: =IF(B1>0,SUM(I3:I999)/C1,0) -> 4.8903967
A2: {=IF(ROW(A2:A999)=2,"PLACA",IFERROR(VLOOKUP(B2:B999,C_PISTOLEO!A:C,3,0),""))} -> PLACA | J2: {=IF(ROW(A2:A999)=2,"PLAN CREDITO",IF(A2:A999>0,IFERROR(VLOOKUP(B2:B999,'PLANILLAS(R)'!B:B,1,0),"CREDITO"),""))} -> PLAN CREDITO
B3: Factura | C3: Carga | D3: Sencillo | E3: Nombre | F3: Dir 1 | G3: Municipio | H3: SUM of Cant Env | I3: SUM of Volumen | J3: FACTURA
B4: AFE7180384 | C4: L010894328 | D4: USC439 | E4: Almacenes Exito S.A. | F4: Calle 43 Sur # 48-127 Cedi Vegas | G4: Envigado | H4: 25 | I4: 0 | J4: CREDITO
B5: AFE7180385 | C5: L010894328 | D5: USC439 | E5: Cencosud Colombia S.A. | F5: Carrera 48 # 25 sur -136 Envigado | G5: Medellín | H5: 24 | I5: 0.0275 | J5: CREDITO
B6: AFE7180386 | C6: L010894328 | D6: USC439 | E6: Cencosud Colombia S.A. | F6: Carrera 50 # 27 B - 71 | G6: Bello | H6: 24 | I6: 0.0228 | J6: CREDITO
B7: AFE7180387 | C7: L010894328 | D7: USC439 | E7: Reposteria Mars de Santa Gema S.A.S. | F7: Cl 76 56 47 | G7: Itagui | H7: 1 | I7: 0.0414 | J7: CREDITO
B8: AFE7180388 | C8: L010894328 | D8: USC439 | E8: Antonio`s Gelatos S.A.S. | F8: Kr 51 12 B Sur 55 Ps 1 | G8: Medellín | H8: 18 | I8: 0.5444 | J8: CREDITO
B9: AFE7180389 | C9: L010894328 | D9: USC439 | E9: Cía.de Alimentos Colombianos Calco S.A. | F9: Carrera 43 A # 25 A-85 | G9: Medellín | H9: 10 | I9: 0.091 | J9: CREDITO
B10: AFE7180390 | C10: L010894328 | D10: USC439 | E10: Nuestra Cocina Artesanal S.A.S. | F10: Kr 43 C 61 Sur 10 | G10: Sabaneta | H10: 17 | I10: 0.3342 | J10: CREDITO
B11: AFE7180391 | C11: L010894328 | D11: USC439 | E11: Pastelpan las Envinadas | F11: Carrera 50 GG # 10 B sur-81 | G11: Medellín | H11: 10 | I11: 0.1751 | J11: CREDITO
B12: AFE7180392 | C12: L010894328 | D12: USC439 | E12: Chef Burger Company S.A.S. | F12: Kr 43 25a 127 | G12: Medellín | H12: 8 | I12: 0.3344 | J12: CREDITO
B13: AFE7180393 | C13: L010894328 | D13: USC439 | E13: Activos Y Gastronomia Dos S.A.S. | F13: Cl 72 64 C 96 Bg Centro Norte Caribe 109 | G13: Medellín | H13: 20 | I13: 1.196 | J13: CREDITO
B14: AFE7180394 | C14: L010894328 | D14: USC439 | E14: Cocorollo El Limonar S.A.S. | F14: Vda Portachuelo Auto Norte Km 20 | G14: Girardota | H14: 16 | I14: 0.3536 | J14: CREDITO
B15: AFE7180395 | C15: L010894328 | D15: USC439 | E15: Arary S.A.S. | F15: Km 5+100 Auto Medellin Bogota Bodega 1A | G15: Copacabana | H15: 115 | I15: 6.8806 | J15: CREDITO
... B213: AFE7180897 | C213: L010894328 | D213: USC439 | E213: Jose Alexander Sanchez Muñoz | F213: Kr 53 12 Sur 48 | G213: Medellín | H213: 2 | I213: 0.1084 | J213: AFE7180897
B214: (en blanco) | C214: (en blanco) | D214: (en blanco) | E214: (en blanco) | F214: (en blanco) | G214: (en blanco) | J214: CREDITO
J215: CREDITO
J216: CREDITO
J217: CREDITO
J218: CREDITO
J219: CREDITO
J220: CREDITO
J221: CREDITO
J222: CREDITO
J223: CREDITO
J224: CREDITO
J225: CREDITO
J226: CREDITO
... J999: CREDITO

Sheet INVENTARIO
A3: Item | B3: SUM of Cant Env
A4: D000700T | B4: 2
A5: D001200T | B5: 14
A6: D001201T | B6: 1
A7: D001600T | B7: 12
A8: D001601LT | B8: 19
A9: D001601T | B9: 5
A10: D002300T | B10: 5
A11: D002301LT | B11: 1
A12: D003200T | B12: 1
A13: D004001 | B13: 2
A14: D006801 | B14: 1
A15: D100701 | B15: 7
... A188: RPN21335048 | B188: 1
A189: (en blanco)
A190: Total general | B190: 1090

Sheet PISTOLEO
A1: NumFac: AFE7166747 | B1: TLK297
A2: FecFac: 20251104000000 | B2: TLK297
A3: NitFac: 860013771 | B3: TLK297
A4: DocAdq: 901627943 | B4: TLK297
A5: ValFac: 145000.00 | B5: TLK297
A6: ValIva: 27550.00 | B6: TLK297
A7: ValOtroIm: 0.00 | B7: TLK297
A8: ValFacIm: 172550.00 | B8: TLK297
A9: CUFE-SHA384: 5aacb4a2567dc77be50b4d79109671d8fe9dfd064c90ea314bcc12ffb90e8d53cccbceb60bfcbd27df9475769f6c | B9: TLK297
A10: NumFac: AFE7166726 | B10: SXI118
A11: FecFac: 20251104000000 | B11: SXI118
A12: NitFac: 860013771 | B12: SXI118
... A818: CUFE-SHA384: 0f8c696e80a2e94686d1fce8aac36b0e7be303fc5743c4acc3caf4198bc6c053a87444b1479493399ac844a0f6 | B818: TRD882

Sheet PLACAS
A1: VEJ509 | B1: JAMES | C1: 94252356 | D1: CEL: 3152507903
A2: SVO488 | B2: ALBEIRO | C2: 98762827 | D2: CEL: 3152507903
A3: TKE889 | B3: MATEO | C3: 1007895746 | D3: CEL: 3152507903
A4: GDX508 | B4: CARLOS | C4: 71731792 | D4: CEL: 3152507903
A5: WCQ379 | B5: EDWIN | C5: 1037598750 | D5: CEL: 3152507903
A6: WMP227 | B6: TAVERA | C6: 71765975 | D6: CEL: 3152507903
A7: JYO631 | B7: JAIRO A | C7: 1128450159 | D7: CEL: 3152507903
A8: LKN938 | B8: EDUARDO | C8: 15404230 | D8: CEL: 3152507903
A9: TLK087 | B9: RONALDO | C9: 1039422713 | D9: CEL: 3152507903
A10: LKK194 | B10: LUIS | C10: 1040374984 | D10: CEL:3126792345
A11: TKD564 | B11: LUIS EDUARDO | C11: 1017227949 | D11: CEL: 3152507903
A12: LJZ964 | B12: EMILIO | C12: 71739507 | D12: CEL: 3015809022
... A58: LKN 291 | B58: DANIEL RAMIREZ | C58: 8433512 | D58: CEL: 3205250365

Sheet FACTURAS(PN)
D1: PLANILLA DE CONTROL DE ENTREGAS PLAN NORMAL
E4: DEVOLUCIONES | J4: CHEQUES RECIBIDOS
A5: {='F(L)_Pn'!A1:N956} -> U. NEG | B5: FACTURA | C5: # INTERNO | D5: VALOR | E5: RMA | F5: VALOR | G5: TOTAL PAGAR | H5: C.PAG | I5: F.PAGO | J5: CLIENTE | K5: No. CHEQUE | L5: BANCO | M5: VALOR | N5: PLACA
A6: 0 | B6: #N/A | C6: 0 | D6: 0 | E6: 0 | F6: 0 | G6: 0 | H6: 0 | I6: 0 | J6: 0 | K6: 0 | L6: 0 | M6: 0 | N6: #N/A
A7: 0 | B7: 0 | C7: 0 | D7: 0 | E7: 0 | F7: 0 | G7: 0 | H7: 0 | I7: 0 | J7: 0 | K7: 0 | L7: 0 | M7: 0
A8: 0 | B8: 0 | C8: 0 | D8: 0 | E8: 0 | F8: 0 | G8: 0 | H8: 0 | I8: 0 | J8: 0 | K8: 0 | L8: 0 | M8: 0
A9: 0 | B9: 0 | C9: 0 | D9: 0 | E9: 0 | F9: 0 | G9: 0 | H9: 0 | I9: 0 | J9: 0 | K9: 0 | L9: 0 | M9: 0
A10: 0 | B10: 0 | C10: 0 | D10: 0 | E10: 0 | F10: 0 | G10: 0 | H10: 0 | I10: 0 | J10: 0 | K10: 0 | L10: 0 | M10: 0
A11: 0 | B11: 0 | C11: 0 | D11: 0 | E11: 0 | F11: 0 | G11: 0 | H11: 0 | I11: 0 | J11: 0 | K11: 0 | L11: 0 | M11: 0
A12: 0 | B12: 0 | C12: 0 | D12: 0 | E12: 0 | F12: 0 | G12: 0 | H12: 0 | I12: 0 | J12: 0 | K12: 0 | L12: 0 | M12: 0
A13: 0 | B13: 0 | C13: 0 | D13: 0 | E13: 0 | F13: 0 | G13: 0 | H13: 0 | I13: 0 | J13: 0 | K13: 0 | L13: 0 | M13: 0
A14: 0 | B14: 0 | C14: 0 | D14: 0 | E14: 0 | F14: 0 | G14: 0 | H14: 0 | I14: 0 | J14: 0 | K14: 0 | L14: 0 | M14: 0
A15: 0 | B15: 0 | C15: 0 | D15: 0 | E15: 0 | F15: 0 | G15: 0 | H15: 0 | I15: 0 | J15: 0 | K15: 0 | L15: 0 | M15: 0
A16: 0 | B16: 0 | C16: 0 | D16: 0 | E16: 0 | F16: 0 | G16: 0 | H16: 0 | I16: 0 | J16: 0 | K16: 0 | L16: 0 | M16: 0
A17: 0 | B17: 0 | C17: 0 | D17: 0 | E17: 0 | F17: 0 | G17: 0 | H17: 0 | I17: 0 | J17: 0 | K17: 0 | L17: 0 | M17: 0
A18: 0 | B18: 0 | C18: 0 | D18: 0 | E18: 0 | F18: 0 | G18: 0 | H18: 0 | I18: 0 | J18: 0 | K18: 0 | L18: 0 | M18: 0
... A956: 0 | B956: 0 | C956: 0 | D956: 0 | E956: 0 | F956: 0 | G956: 0 | H956: 0 | I956: 0 | J956: 0 | K956: 0 | L956: 0 | M956: 0

Sheet PLANILLAS(R)
K1: MD
K2: CONSIGNACIONES
H3: TOTAL FACTURADO | I3: 45537135
B4: No | C4: L010894328
B5: Fecha Envío | C5: 45971
B6: Placa | C6: USC439 | F6: TOTAL EFECTIVO | G6: =SUMIF(I:I,"EF",G:G) -> 42093870
B7: Conductor | C7: 14324467 DIOMER BELTRAN RUBIO
B8: Despachador | C8: 3966 LOPEZ,WILMAR | I8: TOTAL | J8: =SUM(J4:J7) -> 0
B9: Fecha Planilla | H9: TOTAL REDESPACHO | K9: =IF(J8<>G6,J8-G6,"") -> -42093870
H10: DESCUENTO TRANSP. | I10: 45537135 | J10: REF DESCUEN
D12: DEVOLUCIONES | I12: CHEQUES RECIBIDOS
A13: U. NEG | B13: FACTURA | C13: # INTERNO | D13: VALOR | E13: RMA | F13: VALOR | G13: TOTAL PAGAR | H13: C.PAG | I13: F.PAGO | J13: CLIENTE | K13: No. CHEQUE | L13: BANCO | M13: PLACA | N13: {=IFERROR(IF(B13:B1958>0,VLOOKUP(B13:B1958,FACTURAS!B:G,6,0),""),"")} -> Municipio
A14: AJV21 | B14: AFE7180720 | C14: 12396593 | D14: 1337560 | G14: 1337560 | H14: EF | I14: EF | J14: EF | K14: CPR1036840 | N14: Bello
A15: AJV21 | B15: AFE7180721 | C15: 12396594 | D15: 262276 | G15: 262276 | H15: EF | I15: EF | J15: EF | K15: CPR1045020 | N15: Medellín
A16: AJV21 | B16: AFE7180722 | C16: 12396595 | D16: 283696 | G16: 283696 | H16: EF | I16: EF | J16: EF | K16: CPR1031775 | N16: Medellín
A17: AJV21 | B17: AFE7180723 | C17: 12396596 | D17: 161840 | G17: 161840 | H17: 030D | I17: CR | J17: CR | K17: CPR1020258 | N17: Copacabana
A18: AJV21 | B18: AFE7180724 | C18: 12396597 | D18: 199920 | G18: 199920 | H18: EF | I18: EF | J18: EF | K18: CPR1044746 | N18: Envigado
A19: AJV21 | B19: AFE7180725 | C19: 12396598 | D19: 96509 | G19: 96509 | H19: EF | I19: EF | J19: EF | K19: CPR1053940 | N19: Guarne
A20: AJV21 | B20: AFE7180726 | C20: 12396599 | D20: 97342 | G20: 97342 | H20: EF | I20: EF | J20: EF | K20: CPR1054675 | N20: Guarne
A21: AJV21 | B21: AFE7180727 | C21: 12396600 | D21: 548352 | G21: 548352 | H21: EF | I21: EF | J21: EF | K21: CPR1019721 | N21: Guarne
A22: AJV21 | B22: AFE7180728 | C22: 12396601 | D22: 109599 | G22: 109599 | H22: EF | I22: EF | J22: EF | K22: CPR1043846 | N22: Medellín
A23: AJV21 | B23: AFE7180729 | C23: 12396602 | D23: 335461 | G23: 335461 | H23: EF | I23: EF | J23: EF | K23: CPR1030195 | N23: Medellín
A24: AJV21 | B24: AFE7180730 | C24: 12396603 | D24: 91987 | G24: 91987 | H24: EF | I24: EF | J24: EF | K24: CPR1044784 | N24: Guarne
A25: AJV21 | B25: AFE7180731 | C25: 12396604 | D25: 187544 | G25: 187544 | H25: EF | I25: EF | J25: EF | K25: CPR1045733 | N25: Guarne
... A191: AJV21 | B191: AFE7180897 | C191: 12396770 | D191: 300356 | G191: 300356 | H191: EF | I191: EF | J191: EF | K191: CPR1055576 | N191: Medellín

Sheet MINI_L
J1: BANCO | K1: VALOR | L1: COMPROBANTE | M1: FECHA
J2: bancolombia
J3: bancolombia
J4: bancolombia
J5: bancolombia
A6: NUMERO DE L | B6: ='PLANILLAS(R)'!C4 -> L010894328 | J6: PARCIAL
A7: Fecha Envío | B7: =FACTURAS!F1 -> 45941 | G7: # ENTREGAS | J7: DEVOLUCION
A8: Placa | G8: DEV-REPISE | J8: DIFERENCIA | K8: =K10-SUM(K2:K7) -> 0
A9: Conductor | B9: =VLOOKUP(B8,PLACAS!$A:$D,2,0) -> #N/A | D9: =VLOOKUP(B8,PLACAS!$A:$D,3,0) -> #N/A
A10: Despachador | B10: ANDRES CETRE | J10: TOTAL $ | K10: =SUM(D13:D996) -> 0
D11: 217-392356-56 CUENTA CORRIENTE BANCOLOMBIA
A12: U. NEG | B12: FACTURA | C12: # INTERNO | D12: VALOR | E12: RMA | F12: VALOR | G12: TOTAL PAGAR | H12: C.PAG | I12: F.PAGO | J12: CLIENTE | K12: No. CHEQUE | L12: BANCO

Sheet LKN291 DANIEL RAMIREZ
J1: BANCO | K1: VALOR | L1: COMPROBANTE | M1: FECHA
J2: bancolombia
J3: bancolombia
J4: bancolombia
J5: bancolombia
A6: NUMERO DE L | B6: ='PLANILLAS(R)'!C4 -> L010894328 | J6: PARCIAL
A7: Fecha Envío | B7: =FACTURAS!F1 -> 45941 | G7: # ENTREGAS | J7: DEVOLUCION
A8: Placa | B8: LKN 291 | G8: DEV-REPISE | J8: DIFERENCIA | K8: =K10-SUM(K2:K7) -> 0
A9: Conductor | B9: =VLOOKUP(B8,PLACAS!$A:$D,2,0) -> DANIEL RAMIREZ | D9: =VLOOKUP(B8,PLACAS!$A:$D,3,0) -> 8433512
A10: Despachador | B10: ANDRES CETRE | J10: TOTAL $ | K10: =SUM(D13:D974) -> 0
D11: 217-392356-56 CUENTA CORRIENTE BANCOLOMBIA
A12: U. NEG | B12: FACTURA | C12: # INTERNO | D12: VALOR | E12: RMA | F12: VALOR | G12: TOTAL PAGAR | H12: C.PAG | I12: F.PAGO | J12: CLIENTE | K12: No. CHEQUE | L12: BANCO

Sheet PXK108 ANDRES QUICENO
J1: BANCO | K1: VALOR | L1: COMPROBANTE | M1: FECHA
J2: bancolombia
J3: bancolombia
J4: bancolombia
J5: bancolombia
A6: NUMERO DE L | B6: ='PLANILLAS(R)'!C4 -> L010894328 | J6: PARCIAL
A7: Fecha Envío | B7: =FACTURAS!F1 -> 45941 | G7: # ENTREGAS | J7: DEVOLUCION
A8: Placa | B8: PXK 108 | G8: DEV-REPISE | J8: DIFERENCIA | K8: =K10-SUM(K2:K7) -> 0
A9: Conductor | B9: =VLOOKUP(B8,PLACAS!$A:$D,2,0) -> ANDRES QUICENO | D9: =VLOOKUP(B8,PLACAS!$A:$D,3,0) -> 1007814097
A10: Despachador | B10: ANDRES CETRE | J10: TOTAL $ | K10: =SUM(D13:D970) -> 0
D11: 217-392356-56 CUENTA CORRIENTE BANCOLOMBIA
A12: U. NEG | B12: FACTURA | C12: # INTERNO | D12: VALOR | E12: RMA | F12: VALOR | G12: TOTAL PAGAR | H12: C.PAG | I12: F.PAGO | J12: CLIENTE | K12: No. CHEQUE | L12: BANCO

Sheet SXI118 WILLIAM GIL
J1: BANCO | K1: VALOR | L1: COMPROBANTE | M1: FECHA
J2: bancolombia
J3: bancolombia
J4: bancolombia
J5: bancolombia
A6: NUMERO DE L | B6: ='PLANILLAS(R)'!C4 -> L010894328 | J6: PARCIAL
A7: Fecha Envío | B7: =FACTURAS!F1 -> 45941 | G7: # ENTREGAS | J7: DEVOLUCION
A8: Placa | B8: SXI118 | G8: DEV-REPISE | J8: DIFERENCIA | K8: =K10-SUM(K2:K7) -> 0
A9: Conductor | B9: =VLOOKUP(B8,PLACAS!$A:$D,2,0) -> WILLIAM GIL | D9: =VLOOKUP(B8,PLACAS!$A:$D,3,0) -> 71578229
A10: Despachador | B10: ANDRES CETRE | J10: TOTAL $ | K10: =SUM(D13:D972) -> 0
D11: 217-392356-56 CUENTA CORRIENTE BANCOLOMBIA
A12: U. NEG | B12: FACTURA | C12: # INTERNO | D12: VALOR | E12: RMA | F12: VALOR | G12: TOTAL PAGAR | H12: C.PAG | I12: F.PAGO | J12: CLIENTE | K12: No. CHEQUE | L12: BANCO

Sheet NNM419 FRANK
J1: BANCO | K1: VALOR | L1: COMPROBANTE | M1: FECHA
J2: bancolombia
J3: bancolombia
J4: bancolombia
J5: bancolombia
A6: NUMERO DE L | B6: ='PLANILLAS(R)'!C4 -> L010894328 | J6: PARCIAL
A7: Fecha Envío | B7: =FACTURAS!F1 -> 45941 | G7: # ENTREGAS | J7: DEVOLUCION
A8: Placa | B8: NNM 419 | G8: DEV-REPISE | J8: DIFERENCIA | K8: =K10-SUM(K2:K7) -> 0
A9: Conductor | B9: =VLOOKUP(B8,PLACAS!$A:$D,2,0) -> FRANK GAVIRIA | D9: =VLOOKUP(B8,PLACAS!$A:$D,3,0) -> 1152710529
A10: Despachador | B10: ANDRES CETRE | J10: TOTAL $ | K10: =SUM(D13:D969) -> 0
D11: 217-392356-56 CUENTA CORRIENTE BANCOLOMBIA
A12: U. NEG | B12: FACTURA | C12: # INTERNO | D12: VALOR | E12: RMA | F12: VALOR | G12: TOTAL PAGAR | H12: C.PAG | I12: F.PAGO | J12: CLIENTE | K12: No. CHEQUE | L12: BANCO

Sheet TLK297 HERNANDO
J1: BANCO | K1: VALOR | L1: COMPROBANTE | M1: FECHA
J2: bancolombia
J3: bancolombia
J4: bancolombia
J5: bancolombia
A6: NUMERO DE L | B6: ='PLANILLAS(R)'!C4 -> L010894328 | J6: PARCIAL
A7: Fecha Envío | B7: =FACTURAS!F1 -> 45941 | G7: # ENTREGAS | J7: DEVOLUCION
A8: Placa | B8: TLK 297 | G8: DEV-REPISE | J8: DIFERENCIA | K8: =K10-SUM(K2:K7) -> 0
A9: Conductor | B9: =VLOOKUP(B8,PLACAS!$A:$D,2,0) -> DUVAN CORTEZ | D9: =VLOOKUP(B8,PLACAS!$A:$D,3,0) -> 1152216210
A10: Despachador | B10: ANDRES CETRE | J10: TOTAL $ | K10: =SUM(D13:D969) -> 0
D11: 217-392356-56 CUENTA CORRIENTE BANCOLOMBIA
A12: U. NEG | B12: FACTURA | C12: # INTERNO | D12: VALOR | E12: RMA | F12: VALOR | G12: TOTAL PAGAR | H12: C.PAG | I12: F.PAGO | J12: CLIENTE | K12: No. CHEQUE | L12: BANCO

Sheet TOQ606 JOEL
J1: BANCO | K1: VALOR | L1: COMPROBANTE | M1: FECHA
J2: bancolombia
J3: bancolombia
J4: bancolombia
J5: bancolombia
A6: NUMERO DE L | B6: ='PLANILLAS(R)'!C4 -> L010894328 | J6: PARCIAL
A7: Fecha Envío | B7: =FACTURAS!F1 -> 45941 | G7: # ENTREGAS | J7: DEVOLUCION
A8: Placa | B8: TOQ 606 | G8: DEV-REPISE | J8: DIFERENCIA | K8: =K10-SUM(K2:K7) -> 0
A9: Conductor | B9: =VLOOKUP(B8,PLACAS!$A:$D,2,0) -> JOEL GAVIRIA | D9: =VLOOKUP(B8,PLACAS!$A:$D,3,0) -> 15048987
A10: Despachador | B10: ANDRES CETRE | J10: TOTAL $ | K10: =SUM(D13:D976) -> 0
D11: 217-392356-56 CUENTA CORRIENTE BANCOLOMBIA
A12: U. NEG | B12: FACTURA | C12: # INTERNO | D12: VALOR | E12: RMA | F12: VALOR | G12: TOTAL PAGAR | H12: C.PAG | I12: F.PAGO | J12: CLIENTE | K12: No. CHEQUE | L12: BANCO

Sheet WCQ379 EDWIN FRANCO
J1: BANCO | K1: VALOR | L1: COMPROBANTE | M1: FECHA
J2: bancolombia
J3: bancolombia
J4: bancolombia
J5: bancolombia
A6: NUMERO DE L | B6: ='PLANILLAS(R)'!C4 -> L010894328 | J6: PARCIAL
A7: Fecha Envío | B7: =FACTURAS!F1 -> 45941 | G7: # ENTREGAS | J7: DEVOLUCION
A8: Placa | B8: WCQ379 | G8: DEV-REPISE | J8: DIFERENCIA | K8: =K10-SUM(K2:K7) -> 0
A9: Conductor | B9: =VLOOKUP(B8,PLACAS!$A:$D,2,0) -> EDWIN | D9: =VLOOKUP(B8,PLACAS!$A:$D,3,0) -> 1037598750
A10: Despachador | B10: ANDRES CETRE | J10: TOTAL $ | K10: =SUM(D13:D974) -> 0
D11: 217-392356-56 CUENTA CORRIENTE BANCOLOMBIA
A12: U. NEG | B12: FACTURA | C12: # INTERNO | D12: VALOR | E12: RMA | F12: VALOR | G12: TOTAL PAGAR | H12: C.PAG | I12: F.PAGO | J12: CLIENTE | K12: No. CHEQUE | L12: BANCO

Sheet GDX508 CARLOS MARIN
J1: BANCO | K1: VALOR | L1: COMPROBANTE | M1: FECHA
J2: bancolombia
J3: bancolombia
J4: bancolombia
J5: bancolombia
A6: NUMERO DE L | B6: ='PLANILLAS(R)'!C4 -> L010894328 | J6: PARCIAL
A7: Fecha Envío | B7: =FACTURAS!F1 -> 45941 | G7: # ENTREGAS | J7: DEVOLUCION
A8: Placa | B8: GDX508 | G8: DEV-REPISE | J8: DIFERENCIA | K8: =K10-SUM(K2:K7) -> 0
A9: Conductor | B9: =VLOOKUP(B8,PLACAS!$A:$D,2,0) -> CARLOS | D9: =VLOOKUP(B8,PLACAS!$A:$D,3,0) -> 71731792
A10: Despachador | B10: ANDRES CETRE | J10: TOTAL $ | K10: =SUM(D13:D970) -> 0
D11: 217-392356-56 CUENTA CORRIENTE BANCOLOMBIA
A12: U. NEG | B12: FACTURA | C12: # INTERNO | D12: VALOR | E12: RMA | F12: VALOR | G12: TOTAL PAGAR | H12: C.PAG | I12: F.PAGO | J12: CLIENTE | K12: No. CHEQUE | L12: BANCO

Sheet STY099 MATEO LOAIZA
J1: BANCO | K1: VALOR | L1: COMPROBANTE | M1: FECHA
J2: bancolombia
J3: bancolombia
J4: bancolombia
J5: bancolombia
A6: NUMERO DE L | B6: ='PLANILLAS(R)'!C4 -> L010894328 | J6: PARCIAL
A7: Fecha Envío | B7: =FACTURAS!F1 -> 45941 | G7: # ENTREGAS | J7: DEVOLUCION
A8: Placa | B8: STY 099 | G8: DEV-REPISE | J8: DIFERENCIA | K8: =K10-SUM(K2:K7) -> 0
A9: Conductor | B9: =VLOOKUP(B8,PLACAS!$A:$D,2,0) -> MATEO LOAIZA | D9: =VLOOKUP(B8,PLACAS!$A:$D,3,0) -> 1007895746
A10: Despachador | B10: ANDRES CETRE | J10: TOTAL $ | K10: =SUM(D13:D969) -> 0
D11: 217-392356-56 CUENTA CORRIENTE BANCOLOMBIA
A12: U. NEG | B12: FACTURA | C12: # INTERNO | D12: VALOR | E12: RMA | F12: VALOR | G12: TOTAL PAGAR | H12: C.PAG | I12: F.PAGO | J12: CLIENTE | K12: No. CHEQUE | L12: BANCO

Sheet TKD564 LUIS CONTRERAS
J1: BANCO | K1: VALOR | L1: COMPROBANTE | M1: FECHA
J2: bancolombia
J3: bancolombia
J4: bancolombia
J5: bancolombia
A6: NUMERO DE L | B6: ='PLANILLAS(R)'!C4 -> L010894328 | J6: PARCIAL
A7: Fecha Envío | B7: =FACTURAS!F1 -> 45941 | G7: # ENTREGAS | J7: DEVOLUCION
A8: Placa | B8: TKD564 | G8: DEV-REPISE | J8: DIFERENCIA | K8: =K10-SUM(K2:K7) -> 0
A9: Conductor | B9: =VLOOKUP(B8,PLACAS!$A:$D,2,0) -> LUIS EDUARDO | D9: =VLOOKUP(B8,PLACAS!$A:$D,3,0) -> 1017227949
A10: Despachador | B10: ANDRES CETRE | J10: TOTAL $ | K10: =SUM(D13:D971) -> 0
D11: 217-392356-56 CUENTA CORRIENTE BANCOLOMBIA
A12: U. NEG | B12: FACTURA | C12: # INTERNO | D12: VALOR | E12: RMA | F12: VALOR | G12: TOTAL PAGAR | H12: C.PAG | I12: F.PAGO | J12: CLIENTE | K12: No. CHEQUE | L12: BANCO

Sheet SVO488 JUAN ESTEBAN
J1: BANCO | K1: VALOR | L1: COMPROBANTE | M1: FECHA
J2: bancolombia
J3: bancolombia
J4: bancolombia
J5: bancolombia
A6: NUMERO DE L | B6: ='PLANILLAS(R)'!C4 -> L010894328 | J6: PARCIAL
A7: Fecha Envío | B7: =FACTURAS!F1 -> 45941 | G7: # ENTREGAS | J7: DEVOLUCION
A8: Placa | B8: SVO 488 | G8: DEV-REPISE | J8: DIFERENCIA | K8: =K10-SUM(K2:K7) -> 0
A9: Conductor | B9: =VLOOKUP(B8,PLACAS!$A:$D,2,0) -> JUAN ESTEBAN MONCADA | D9: =VLOOKUP(B8,PLACAS!$A:$D,3,0) -> 1000206476
A10: Despachador | B10: ANDRES CETRE | J10: TOTAL $ | K10: =SUM(D13:D969) -> 0
D11: 217-392356-56 CUENTA CORRIENTE BANCOLOMBIA
A12: U. NEG | B12: FACTURA | C12: # INTERNO | D12: VALOR | E12: RMA | F12: VALOR | G12: TOTAL PAGAR | H12: C.PAG | I12: F.PAGO | J12: CLIENTE | K12: No. CHEQUE | L12: BANCO

Sheet VEJ509 JAMES SALGADO
J1: BANCO | K1: VALOR | L1: COMPROBANTE | M1: FECHA
J2: bancolombia
J3: bancolombia
J4: bancolombia
J5: bancolombia
A6: NUMERO DE L | B6: ='PLANILLAS(R)'!C4 -> L010894328 | J6: PARCIAL
A7: Fecha Envío | B7: =FACTURAS!F1 -> 45941 | G7: # ENTREGAS | J7: DEVOLUCION
A8: Placa | B8: VEJ509 | G8: DEV-REPISE | J8: DIFERENCIA | K8: =K10-SUM(K2:K7) -> 0
A9: Conductor | B9: =VLOOKUP(B8,PLACAS!$A:$D,2,0) -> JAMES | D9: =VLOOKUP(B8,PLACAS!$A:$D,3,0) -> 94252356
A10: Despachador | B10: ANDRES CETRE | J10: TOTAL $ | K10: =SUM(D13:D969) -> 0
D11: 217-392356-56 CUENTA CORRIENTE BANCOLOMBIA
A12: U. NEG | B12: FACTURA | C12: # INTERNO | D12: VALOR | E12: RMA | F12: VALOR | G12: TOTAL PAGAR | H12: C.PAG | I12: F.PAGO | J12: CLIENTE | K12: No. CHEQUE | L12: BANCO

Sheet C_PISTOLEO
A1: {=IFERROR(RIGHT($B$1:$B3032,LEN($B$1:$B3032)-FIND("AFE",$B$1:$B3032)+1),"")} -> AFE7166747 | B1: {=PISTOLEO!$A:$B} -> NumFac: AFE7166747 | C1: TLK297 | E1: {=IFERROR(RIGHT($F$1:$F3032,LEN($F$1:$F3032)-FIND("AFE",$F$1:$F3032)+1),"")} -> AFE5224264 | F1: {=P_DEVOLUCIONES!A:A} -> NumFac: AFE5224264 | H1: =IFERROR(__xludf.DUMMYFUNCTION("JOIN(""' or Col1= '"",Filter(E:E,lenb(E:E)>0))"),"AFE5224264' or Col1= 'AFE5217011' or Col1= 'AFE5224412' or Col1= 'AFE5224497' or Col1= 'AFE5224506' or Col1= 'AFE5225616' or Col1= 'AFE5224400' or Col1= 'AFE5224364' or Col1= 'AFE5224277' or Col1= 'AFE5224388' or Col1= 'AFE5224321' or Col1= 'AFE5224445' o"&"r Col1= 'AFE5224456' or Col1= 'AFE5224257' or Col1= 'AFE5224479' or Col1= 'AFE5224271' or Col1= 'AFE5224440' or Col1= 'AFE5224434' or Col1= 'AFE5224372' or Col1= 'AFE5224430' or Col1= 'AFE5224262' or Col1= 'AFE5224509' or Col1= 'AFE5224312' or Col1= 'AFE5"&"224490' or Col1= 'AFE5224437' or Col1= 'AFE5211320' or Col1= 'AFE5207923") -> AFE5224264' or Col1= 'AFE5217011' or Col1= 'AFE5224412' or Col1= 'AFE5224497' or Col1= 'AFE5224506' or Col1= 'AFE5225616' or Col1= 'AFE5224400' or Col1= 'AFE5224364' or Col1= 'AFE5224277' or Col1= 'AFE5224388' or Col1= 'AFE5224321' or Col1= 'AFE5224445' or Col1= 'AFE5224456' or Col1= 'AFE5224257' or Col1= 'AFE5224479' or Col1= 'AFE5224271' or Col1= 'AFE5224440' or Col1= 'AFE5224434' or Col1= 'AFE5224372' or Col1= 'AFE5224430' or Col1= 'AFE5224262' or Col1= 'AFE5224509' or Col1= 'AFE5224312' or Col1= 'AFE5224490' or Col1= 'AFE5224437' or Col1= 'AFE5211320' or Col1= 'AFE5207923
B2: FecFac: 20251104000000 | C2: TLK297 | F2: FecFac: 20231223000000
B3: NitFac: 860013771 | C3: TLK297 | F3: NitFac: 860013771
B4: DocAdq: 901627943 | C4: TLK297 | F4: DocAdq: 1053806846
B5: ValFac: 145000.00 | C5: TLK297 | F5: ValFac: 36500.00
B6: ValIva: 27550.00 | C6: TLK297 | F6: ValIva: 6935.00
B7: ValOtroIm: 0.00 | C7: TLK297 | F7: ValOtroIm: 0.00
B8: ValFacIm: 172550.00 | C8: TLK297 | F8: ValFacIm: 43435.00
B9: CUFE-SHA384: 5aacb4a2567dc77be50b4d79109671d8fe9dfd064c90ea314bcc12ffb90e8d53cccbceb60bfcbd27df9475769f6c | C9: TLK297 | F9: CUFE-SHA384: ee35b420b97ab0d157c8c94ad3d8b234fd993c1e294ace717a0d37373e234a151a17ef58b4a7a32a8ce636a18b1348
A10: AFE7166726 | B10: NumFac: AFE7166726 | C10: SXI118 | E10: AFE5217011 | F10: NumFac: AFE5217011
B11: FecFac: 20251104000000 | C11: SXI118 | F11: FecFac: 20231221000000
B12: NitFac: 860013771 | C12: SXI118 | F12: NitFac: 860013771
B13: DocAdq: 901579186 | C13: SXI118 | F13: DocAdq: 1037600920
B14: ValFac: 69300.00 | C14: SXI118 | F14: ValFac: 114400.00
B15: ValIva: 13167.00 | C15: SXI118 | F15: ValIva: 21736.00
B16: ValOtroIm: 0.00 | C16: SXI118 | F16: ValOtroIm: 0.00
B17: ValFacIm: 82467.00 | C17: SXI118 | F17: ValFacIm: 136136.00
B18: CUFE-SHA384: 246737cdf9a9eb5198f6b4257c0d40ca243fd13b4808fad9e3603f7a161c89db35697b5b1b05711535421844c37268 | C18: SXI118 | F18: CUFE-SHA384: 7b6d61610203b6e8a9f9f6ba468ace02874e2990fe00d22171b9533815b32e6c9dfe016f2667bf92818784e1b4b
A19: AFE7166763 | B19: NumFac: AFE7166763 | C19: SXI118 | E19: AFE5224412 | F19: NumFac: AFE5224412
B20: FecFac: 20251104000000 | C20: SXI118 | F20: FecFac: 20231223000000
B21: NitFac: 860013771 | C21: SXI118 | F21: NitFac: 860013771
B22: DocAdq: 800223589 | C22: SXI118 | F22: DocAdq: 21482766
B23: ValFac: 143900.00 | C23: SXI118 | F23: ValFac: 131300.00
B24: ValIva: 27341.00 | C24: SXI118 | F24: ValIva: 24947.00
B25: ValOtroIm: 0.00 | C25: SXI118 | F25: ValOtroIm: 0.00
B26: ValFacIm: 171241.00 | C26: SXI118 | F26: ValFacIm: 156247.00
B27: CUFE-SHA384: 0886930e7f50076341f0569376732d6ba0d5cc06b5fcf061724659945d9dd6dd64b6b156f3866295c72f4b2dfd30 | C27: SXI118 | F27: CUFE-SHA384: f7a3587e86944df0bfdecb5a1c9b9e9da8e0f3da82fe61b6c25771cb25a569a270a8d1193cba76848f8f425410e22
A28: AFE7166761 | B28: NumFac: AFE7166761 | C28: SXI118 | E28: AFE5224497 | F28: NumFac: AFE5224497
B29: FecFac: 20251104000000 | C29: SXI118 | F29: FecFac: 20231223000000
B30: NitFac: 860013771 | C30: SXI118 | F30: NitFac: 860013771
B31: DocAdq: 15501931 | C31: SXI118 | F31: DocAdq: 901356600
B32: ValFac: 717600.00 | C32: SXI118 | F32: ValFac: 192100.00
B33: ValIva: 136344.00 | C33: SXI118 | F33: ValIva: 36499.00
B34: ValOtroIm: 0.00 | C34: SXI118 | F34: ValOtroIm: 0.00
B35: ValFacIm: 853944.00 | C35: SXI118 | F35: ValFacIm: 228599.00
A36: AFE7166687 | B36: NumFac: AFE7166687 | C36: SXI118 | F36: CUFE-SHA384: 900c251cb7378e464b2f637515e4cdfac354cddb138ac5b91e32d5328ccdd98a429108bc1082301892fb71eaebf3
B37: FecFac: 20251104000000 | C37: STY099 | E37: AFE5224506 | F37: NumFac: AFE5224506
B38: NitFac: 860013771 | C38: STY099 | F38: FecFac: 20231223000000
B39: DocAdq: 8401658 | C39: STY099 | F39: NitFac: 860013771
B40: ValFac: 689500.00 | C40: STY099 | F40: DocAdq: 43710545
...

Sheet P_DEVOLUCIONES
A1: NumFac: AFE5224264
A2: FecFac: 20231223000000
A3: NitFac: 860013771
A4: DocAdq: 1053806846
A5: ValFac: 36500.00
A6: ValIva: 6935.00
A7: ValOtroIm: 0.00
A8: ValFacIm: 43435.00
A9: CUFE-SHA384: ee35b420b97ab0d157c8c94ad3d8b234fd993c1e294ace717a0d37373e234a151a17ef58b4a7a32a8ce636a18b1348
A10: NumFac: AFE5217011
A11: FecFac: 20231221000000
A12: NitFac: 860013771
... A235: AFE5207923

Sheet DEV ENVIO
A1: FECHA FACTURA | B1: CLIENTE | C1: CODIGO CLIENTE | D1: VENDEDOR | E1: NUMERO PLANILLA | F1: REMISION | G1: PEDIDO N° | H1: REFERENCIA | I1: UM | J1: CANTIDAD | K1: MOTIVO DEVOLUCION | L1: UNIDADES DE NEGOCIO

Sheet DEVOLUCIONES
A1: =IFERROR(__xludf.DUMMYFUNCTION("QUERY({'AJ-L'!L:L,'AJ-L'!M:M,'AJ-L'!C:C,'AJ-L'!E:E,'AJ-L'!X:X,'AJ-L'!O:O},""SELECT * WHERE Col1= '""&C_PISTOLEO!H1&""' "",1)"),"Factura") -> Factura | B1: =IFERROR(__xludf.DUMMYFUNCTION("""COMPUTED_VALUE"""),"Pedido") -> Pedido | C1: =IFERROR(__xludf.DUMMYFUNCTION("""COMPUTED_VALUE"""),"Cliente") -> Cliente | D1: =IFERROR(__xludf.DUMMYFUNCTION("""COMPUTED_VALUE"""),"Nombre") -> Nombre | E1: =IFERROR(__xludf.DUMMYFUNCTION("""COMPUTED_VALUE"""),"Carga") -> Carga | F1: =IFERROR(__xludf.DUMMYFUNCTION("""COMPUTED_VALUE"""),"Item") -> Item | G1: devolucion | H1: cantidad | I1: FECHA FACTURA | J1: VENDEDOR | K1: UM | L1: MOTIVO DEVOLUCION | M1: UNIDADES DE NEGOCIO
G2: FALSE | H2: 1 | I2: 45154 | J2: R206 | K2: CJ | M2: AJV21
G3: FALSE
G4: FALSE | H4: 1 | I4: 45154 | J4: R206 | K4: BL | L4: SE VISITA AL CLIENTE DOS VECES | M4: AJV21
G5: FALSE
G6: FALSE
G7: FALSE
G8: FALSE
G9: FALSE
G10: FALSE
G11: FALSE
G12: FALSE
G13: FALSE
G14: FALSE
G15: FALSE
G16: FALSE
... G1500: FALSE

Sheet F(L)_Pn
A1: U. NEG | B1: FACTURA | C1: # INTERNO | D1: VALOR | E1: RMA | F1: VALOR | G1: TOTAL PAGAR | H1: C.PAG | I1: F.PAGO | J1: CLIENTE | K1: No. CHEQUE | L1: BANCO | M1: VALOR | N1: PLACA
B2: =IFERROR(__xludf.DUMMYFUNCTION("FILTER(FACTURAS!B:B,FACTURAS!J:J=""CREDITO"")"),"#N/A") -> #N/A | N2: #N/A
